<?xml version="1.0" ?>
<!-- =================================================================================== -->
<!-- |    This document was autogenerated by xacro from puzzlebot.urdf.xacro           | -->
<!-- |    EDITING THIS FILE BY HAND IS NOT RECOMMENDED                                 | -->
<!-- =================================================================================== -->
<robot name="puzzlebot">
  <link name="base_footprint"/>
  <link name="base_link">
    <visual>
      <origin rpy="0 0 0" xyz="0 0 0"/>
      <geometry>
        <mesh filename="package://puzzlebot_description/meshes/Puzzlebot_Jetson_Lidar_Edition_Base.stl" scale="1.0 1.0 1.0"/>
      </geometry>
      <material name="yellow">
        <color rgba="0.8 0.7 0.0 1.0"/>
      </material>
    </visual>
    <collision>
      <origin rpy="0 0 0" xyz="0 0 0"/>
      <geometry>
        <box size="0.2 0.191 0.1"/>
      </geometry>
    </collision>
    <inertial>
      <mass value="0.5"/>
      <inertia ixx="0.0019367083333333333" ixy="0" ixz="0" iyy="0.0020833333333333337" iyz="0" izz="0.0031867083333333335"/>
    </inertial>
  </link>
  <joint name="base_link_joint" type="fixed">
    <parent link="base_footprint"/>
    <child link="base_link"/>
    <!-- 0.0525 = wheel_radius (0.05) + wheel offset (0.0025) -->
    <origin rpy="0 0 0" xyz="0 0 0.0525"/>
  </joint>
  <link name="wheel_r_link">
    <visual>
      <origin rpy="1.5708 0 0" xyz="0 0 0"/>
      <geometry>
        <mesh filename="package://puzzlebot_description/meshes/Puzzlebot_Wheel.stl" scale="1.0 1.0 1.0"/>
      </geometry>
      <material name="dark_grey">
        <color rgba="0.3 0.3 0.3 1.0"/>
      </material>
    </visual>
    <collision>
      <origin rpy="1.5708 0 0" xyz="0 0 0"/>
      <geometry>
        <cylinder length="0.025" radius="0.05"/>
      </geometry>
    </collision>
    <inertial>
      <mass value="0.05"/>
      <inertia ixx="3.385416666666667e-05" ixy="0" ixz="0" iyy="3.385416666666667e-05" iyz="0" izz="6.250000000000001e-05"/>
    </inertial>
  </link>
  <joint name="wheel_r_joint" type="continuous">
    <parent link="base_link"/>
    <child link="wheel_r_link"/>
    <origin rpy="0 0 0" xyz="0.052 -0.095 -0.0025"/>
    <axis xyz="0 1 0"/>
    <dynamics damping="0.01" friction="0.1"/>
  </joint>
  <link name="wheel_l_link">
    <visual>
      <origin rpy="1.5708 0 0" xyz="0 0 0"/>
      <geometry>
        <mesh filename="package://puzzlebot_description/meshes/Puzzlebot_Wheel.stl" scale="1.0 1.0 1.0"/>
      </geometry>
      <material name="dark_grey">
        <color rgba="0.3 0.3 0.3 1.0"/>
      </material>
    </visual>
    <collision>
      <origin rpy="1.5708 0 0" xyz="0 0 0"/>
      <geometry>
        <cylinder length="0.025" radius="0.05"/>
      </geometry>
    </collision>
    <inertial>
      <mass value="0.05"/>
      <inertia ixx="3.385416666666667e-05" ixy="0" ixz="0" iyy="3.385416666666667e-05" iyz="0" izz="6.250000000000001e-05"/>
    </inertial>
  </link>
  <joint name="wheel_l_joint" type="continuous">
    <parent link="base_link"/>
    <child link="wheel_l_link"/>
    <origin rpy="0 0 0" xyz="0.052 0.095 -0.0025"/>
    <axis xyz="0 1 0"/>
    <dynamics damping="0.01" friction="0.1"/>
  </joint>
  <link name="caster_link">
    <visual>
      <origin rpy="0 0 0" xyz="0 0 0"/>
      <geometry>
        <mesh filename="package://puzzlebot_description/meshes/Puzzlebot_Caster_Wheel.stl" scale="1.0 1.0 1.0"/>
      </geometry>
      <material name="grey">
        <color rgba="0.4 0.4 0.4 1.0"/>
      </material>
    </visual>
    <collision>
      <origin rpy="0 0 0" xyz="0 0 0"/>
      <geometry>
        <sphere radius="0.02"/>
      </geometry>
    </collision>
    <inertial>
      <mass value="0.02"/>
      <inertia ixx="3.2000000000000003e-06" ixy="0" ixz="0" iyy="3.2000000000000003e-06" iyz="0" izz="3.2000000000000003e-06"/>
    </inertial>
  </link>
  <joint name="caster_joint" type="fixed">
    <parent link="base_link"/>
    <child link="caster_link"/>
    <origin rpy="0 0 0" xyz="-0.095 0.0 -0.03"/>
  </joint>
  <link name="lidar_link">
    <visual>
      <origin rpy="0 0 0" xyz="0 0 0"/>
      <geometry>
        <cylinder length="0.04" radius="0.035"/>
      </geometry>
      <material name="black">
        <color rgba="0.1 0.1 0.1 1.0"/>
      </material>
    </visual>
    <collision>
      <origin rpy="0 0 0" xyz="0 0 0"/>
      <geometry>
        <cylinder length="0.04" radius="0.035"/>
      </geometry>
    </collision>
    <inertial>
      <mass value="0.17"/>
      <inertia ixx="7.472916666666668e-05" ixy="0" ixz="0" iyy="7.472916666666668e-05" iyz="0" izz="0.00010412500000000004"/>
    </inertial>
  </link>
  <joint name="lidar_joint" type="fixed">
    <parent link="base_link"/>
    <child link="lidar_link"/>
    <origin rpy="0 0 0" xyz="0.0 0.0 0.08"/>
  </joint>
  <gazebo reference="base_link">
    <material>Gazebo/Yellow</material>
  </gazebo>
  <gazebo reference="wheel_r_link">
    <material>Gazebo/DarkGrey</material>
    <mu1>0.8</mu1>
    <mu2>0.5</mu2>
    <kp>1000000.0</kp>
    <kd>100.0</kd>
  </gazebo>
  <gazebo reference="wheel_l_link">
    <material>Gazebo/DarkGrey</material>
    <mu1>0.8</mu1>
    <mu2>0.5</mu2>
    <kp>1000000.0</kp>
    <kd>100.0</kd>
  </gazebo>
  <gazebo reference="caster_link">
    <material>Gazebo/Grey</material>
    <mu1>0.0</mu1>
    <mu2>0.0</mu2>
  </gazebo>
  <gazebo reference="lidar_link">
    <material>Gazebo/Black</material>
  </gazebo>
  <gazebo>
    <plugin filename="libgazebo_ros_diff_drive.so" name="differential_drive_controller">
      <update_rate>30</update_rate>
      <left_joint>wheel_l_joint</left_joint>
      <right_joint>wheel_r_joint</right_joint>
      <wheel_separation>0.19</wheel_separation>
      <wheel_diameter>0.1</wheel_diameter>
      <max_wheel_torque>50</max_wheel_torque>
      <max_wheel_acceleration>3.0</max_wheel_acceleration>
      <odometry_frame>odom</odometry_frame>
      <robot_base_frame>base_footprint</robot_base_frame>
      <publish_odom>true</publish_odom>
      <publish_odom_tf>true</publish_odom_tf>
      <publish_wheel_tf>true</publish_wheel_tf>
      <ros>
        <remapping>cmd_vel:=cmd_vel</remapping>
        <remapping>odom:=odom</remapping>
      </ros>
    </plugin>
  </gazebo>
  <gazebo reference="lidar_link">
    <sensor name="lidar_sensor" type="ray">
      <pose>0 0 0 0 0 0</pose>
      <always_on>true</always_on>
      <visualize>false</visualize>
      <update_rate>10</update_rate>
      <ray>
        <scan>
          <horizontal>
            <samples>360</samples>
            <resolution>1</resolution>
            <min_angle>-3.14159265</min_angle>
            <max_angle>3.14159265</max_angle>
          </horizontal>
        </scan>
        <range>
          <min>0.08</min>
          <max>5.0</max>
          <resolution>0.015</resolution>
        </range>
        <noise>
          <type>gaussian</type>
          <mean>0.0</mean>
          <stddev>0.01</stddev>
        </noise>
      </ray>
      <plugin filename="libgazebo_ros_ray_sensor.so" name="gazebo_ros_laser">
        <ros>
          <remapping>~/out:=scan</remapping>
        </ros>
        <output_type>sensor_msgs/LaserScan</output_type>
        <frame_name>lidar_link</frame_name>
      </plugin>
    </sensor>
  </gazebo>
</robot>
